Workbook

Sheet Index
A1: 20 CONSTRUCTION DATA ANALYSIS PROBLEMS — FOR WT PARTNERSHIP
A2: Prepared by Gulzar | Data Analyst | Construction-Tech Domain
A4: # | B4: Problem Title | C4: Domain | D4: Sheet Name | E4: Rows in Dataset
A5: 1 | B5: Project Cost Overrun Analysis | C5: Cost Management | D5: P01-CostOverrun | E5: 50
A6: 2 | B6: Material Price Fluctuation Tracker | C6: Procurement | D6: P02-MaterialPrice | E6: 90
A7: 3 | B7: BOQ Variance Analysis | C7: Quantity Surveying | D7: P03-BOQVariance | E7: 60
A8: 4 | B8: Labour Productivity by Trade | C8: Resource Management | D8: P04-LabourProd | E8: 80
A9: 5 | B9: Tender Bid Comparison | C9: Commercial | D9: P05-TenderBid | E9: 40
A10: 6 | B10: Project Delay Root Cause | C10: Project Management | D10: P06-DelayRCA | E10: 60
A11: 7 | B11: Monthly Cash Flow Tracking | C11: Financial Management | D11: P07-CashFlow | E11: 48
A12: 8 | B12: Change Order Impact Analysis | C12: Contract Management | D12: P08-ChangeOrder | E12: 45
A13: 9 | B13: Subcontractor Performance Scorecard | C13: Vendor Management | D13: P09-SubconScore | E13: 30
A14: 10 | B14: Construction Cost Benchmarking | C14: Cost Intelligence | D14: P10-Benchmark | E14: 40
A15: 11 | B15: Risk Register & Probability Matrix | C15: Risk Management | D15: P11-RiskRegister | E15: 35
A16: 12 | B16: Earned Value Management (EVM) | C16: Project Controls | D16: P12-EVM | E16: 36
... A24: 20 | B24: Multi-Project Portfolio Dashboard Data | C24: Portfolio Management | D24: P20-Portfolio | E24: 25

Sheet Analysis Dashboard 
A2: Sheet Name | B2: P01-CostOverrun
B3: Q1. Which country has the highest average cost overrun percentage?
B4: Q2. What is the total budget vs actual cost for each project type? Which type has the worst variance?
B5: Q3. Identify the Top 5 projects with the highest absolute cost overrun (in USD).
B6: Q4. Is there a correlation between project duration and cost overrun percentage?
B7: Q5. Create a pivot table showing average overrun % by Country × Project Type.
B8: Q6. What percentage of projects came in under budget vs over budget?
B9: Q7. Which city has the most cost-efficient project delivery?
A11: Sheet Name | B11: P02-MaterialPrice
B12: Q1. Which material has shown the highest average price increase over 18 months?
B13: Q2. Create a line chart showing monthly price trend for TMT Steel and Cement.
B14: Q3. Which country has the most volatile material pricing? (Use standard deviation)
B15: Q4. Identify the top 3 materials with price increase > 15% — flag them as procurement risk.
B16: Q5. What is the average price change % by material across all months?
B17: Q6. If WT needs 500 MT of steel next quarter, what is the projected cost based on the trend?
A19: Sheet Name | B19: P03-BOQVariance
B20: Q1. Which project has the highest total BOQ variance (in USD)?
B21: Q2. Which trade consistently exceeds BOQ quantities across all 3 projects?
B22: Q3. Identify the top 5 BOQ items with the highest quantity variance %.
B23: Q4. What is the total financial impact of quantity overruns per project?
B24: Q5. Create a waterfall chart showing BOQ Amount vs Actual Amount per trade for Project WT-DC-MUM-01.
B25: Q6. Which items have negative variance (came under BOQ)? What's the saving?
A27: Sheet Name | B27: P04-LabourProd
B28: Q1. Which trade has the highest average productivity per man-hour?
B29: Q2. Is there a productivity difference between projects in India vs Australia?
B30: Q3. Create a box plot (or summary stats) of productivity by trade — which has the most variance?
B31: Q4. On which dates did productivity drop below the 25th percentile? What was the trade?
B32: Q5. What is the optimal crew size (workers count) that maximises productivity for Civil & Structure?
B33: Q6. Calculate total man-hours consumed per project and rank them.
A35: Sheet Name | B35: P05-TenderBid
B36: Q1. For each tender package, which contractor offers the lowest bid? Is the lowest bid always the best choice?
B37: Q2. Create a weighted scoring model: 40% Price, 20% Time, 15% Experience, 15% Safety, 10% Defects. Rank contractors.
B38: Q3. Which contractors appear in multiple packages? What is their average bid competitiveness?
B39: Q4. Identify any contractor with Safety Rating < 3.5 AND Defect Rate > 8% — flag as HIGH RISK.
B40: Q5. What is the total project cost if WT selects the lowest bidder for each package vs the highest-scored bidder?
B41: Q6. Create a scatter plot of Bid Amount vs Completion Days — are cheaper bids slower?
A43: Sheet Name | B43: P06-DelayRCA
B44: Q1. What is the most frequent delay cause category? Create a Pareto chart.
B45: Q2. Which responsible party causes the most total delay days?
B46: Q3. For Project WT-DC-MUM-01, what is the cumulative delay and the dominant cause?
...

Sheet Data Story
A1: THE STORY OF THE PORTFOLIO — 15 PROBLEMS, ONE NARRATIVE
A2: WT Partnership construction data | 50 projects, 25-project portfolio, 3 countries | Every chapter below is tagged to one of the 15 analysed problems. Evidence column is a live link to the Analysis report.
A4: THE STORY IN ONE SHOT
A5: WT wins work in the cheapest-bid market and prices it off benchmarks that are already drifting (P05, P10). The job then leaks value in three places at once: quantities and variations grow beyond the BOQ (P01, P03, P08), the site loses days to other people's decisions and to its own productivity swings (P04, P06, P09, P12), and the supply chain delivers late and dearer than planned (P02, P13). By the time the work is built the money is still outside the business — cash is negative, invoices are ageing, the portfolio is amber (P07, P14, P15). Nine out of ten projects finish over budget, 2024 closed $7.3m cash-negative, $11.9m sits uncollected and 72% of live projects are amber. The cause is not one failure; it is one chain, and it breaks in the same order every time.
A7: Ch | B7: Tag | C7: Chapter headline | D7: The story — what the data is telling us | E7: Evidence (live link to Analysis report) | F7: So what - the move
A8: ACT I — THE PROMISE: how the job is won and priced
A9: 1 | B9: P05 | C9: We buy the cheapest number, not the best bid | D9: Across 5 packages and 13 contractors, the lowest bidder is not the best bidder on 2 of 5 packages. Cheap bids also quote longer programmes (r = -0.25), and 4 bids fail both the safety and defect screens - yet they price competitively enough to win. The discount we celebrate at award is a liability we inherit on site. | E9: ='Analysis report'!A366 -> ANSWER: Awarding every package to the cheapest bid totals $1,01,30,539 (avg score 76.0/100). Awarding to the highest-scored bid totals $1,17,16,950 (avg score 79.1) — $15,86,411 (15.7%) more. That premium buys better programme, safety and defect performance. | F9: Award on the weighted score, not price alone. Hard-gate any bid with safety < 3.5 or defects > 8% before commercial evaluation.
A10: 2 | B10: P10 | C10: The rate base we price from is a moving target | D10: Benchmarks span $670/sqm in India to $3,677/sqm in Australia, and by type from $1,732/sqm (Data Centre) to $3,859/sqm (Hotel). Global rates look flat (-10.2% since 2022) but India has moved +81.6% in the same window. A single blended rate hides a 2.2x spread and an escalating market. | E10: ='Analysis report'!A656 -> ANSWER: Australia is the most expensive market at $3,677/sqm, India the cheapest at $670/sqm — a 448.5% premium. Global average: $2,430/sqm. | F10: Price every pursuit off the country x type cell, then add an explicit escalation line — never a portfolio average.
A11: ACT II — THE BUILD-UP: where the budget quietly disappears
A12: 3 | B12: P01 | C12: Overrun is the norm, not the exception | D12: 45 of 50 projects finished over budget — $2.15bn planned became $2.53bn spent, a 17.6% portfolio overrun. Residential Towers are worst at 26.3%; the single biggest hit is WT-1028 at $2.47cr (33.1%). Duration explains none of it (r = -0.16), so this is not 'long jobs drift' — it is estimating and control, not time. | E12: ='Analysis report'!A26 -> ANSWER: Worst variance = Residential Tower at 26.3% ($6,26,62,924 over budget). Best = Shopping Mall at 3.4%. Portfolio total: $2,15,23,99,053 budget vs $2,53,19,47,246 actual (17.6%). | F12: Stop treating overrun as project-specific. Re-baseline the estimating allowance by type, starting with Residential Tower and Hospital.
A13: 4 | B13: P03 | C13: The BOQ is measured out, line by line | D13: 72 BOQ lines across 3 projects show $18.3L of gross overrun against only $2.4L of savings — net $15.9L, 9.9% above BOQ. MEP-Electrical is over BOQ on 3 of 3 projects; Plastering on the Auckland hospital is 28.9% over. This is the micro-version of Chapter 3: the overrun is assembled from trades, not accidents. | E13: ='Analysis report'!A192 -> ANSWER: Gross overrun impact is $18,28,491 against $2,37,902 of savings, a net $15,90,589 across the three projects. Worst project: WT-OFF-SYD-02 at $7,16,910 net. | F13: Put MEP-Electrical and wet trades on remeasure-and-report monthly, not at final account.
A14: 5 | B14: P08 | C14: Variations: a live book we have not closed | D14: 45 VOs worth $1.43cr in total. $41.9L is approved, but 15 VOs (33%) worth $33.0L are still pending or under review — unquantified exposure sitting outside the forecast. Consultants raise the most VOs (36%); clients drive the most value ($53.0L). Cost and delay are unrelated (r = 0.12), so cheap variations still bite the programme. | E14: ='Analysis report'!A561 -> ANSWER: 15 of 45 change orders (33.3%) are still Pending or Under Review, carrying $32,97,152 of unquantified cost exposure (23.0% of all VO value). That is the number to put in the risk register until these are determined. | F14: Move the $33.0L undetermined VO book into the risk register this month and force a 30-day determination rule.
A15: ACT III — THE GRIND: the site loses days it never gets back
A16: 6 | B16: P04 | C16: Productivity is not low — it is wildly inconsistent | D16: Across 80 crew-days, Civil & Structure averages 3.54 units/man-hour but with the highest variance of any trade (CV 56.4%); the best crew band delivers 4.16 against 2.68 for the weakest. 20 of 80 days fall below the 25th percentile. The problem is not the workforce's ceiling, it is the floor — broken work fronts and unstable crew sizes. | E16: ='Analysis report'!A239 -> ANSWER: Civil & Structure shows the most variance (std dev 2.00, CV 56.4%); the most consistent is MEP - HVAC (std dev 1.13). High variance points to unstable crew mix or interrupted work fronts. | F16: Standardise crew size to the proven 11–15 band and protect work fronts; chase the bad days, not the average.
A17: 7 | B17: P06 | C17: 1,467 lost days — and most are decisions, not weather | D17: 60 delay events cost 1,467 days, roughly $2.20cr at $15k/day. The top cause is RFI response delay (18.3% of events); consultants own 339 days, the most of any party. Weather accounts for only 10.8%, peaking in November. Testing & Commissioning absorbs 291 days — delay concentrates at the end, where there is no float left. | E17: ='Analysis report'!A463 -> ANSWER: At $15,000/day the portfolio's 1,467 delay days cost roughly $2,20,05,000. The most exposed project is WT-DC-MUM-01 at $57,30,000 (382 days); the least is WT-HOS-AKL-03 at $30,75,000. | F17: Put an SLA on RFI turnaround with the consultant, and start T&C planning at 60% completion, not at handover.
A18: 8 | B18: P09 | C18: Subcontractor scoring is not discriminating | D18: 30 scorecards average 3.43 with only 0.08 points separating the best and worst project. Civil & Structure scores lowest on quality (2.45) and carries 48 defects, yet defect count barely correlates with the quality score (r = -0.09). Two subcontractors breach blacklist criteria. The scorecard is currently describing everyone as average. | E18: ='Analysis report'!A639 -> ANSWER: 2 scorecard(s) breach both blacklist criteria and are listed above. Separately 4 score below 3.0 and 13 carry more than 15 defects. | F18: Rewrite the scoring weights so defects actually move the score, and act on the two blacklist breaches.
A19: 9 | B19: P12 | C19: EVM confirms it: behind and getting worse | D19: Over 36 months, SV is negative in 31 of them and CPI declines from 1.042 to 0.900 — efficiency is eroding, not recovering. SPI closes at 0.794. EAC lands at $2.78cr against a $2.50cr BAC, an 11.1% forecast overrun. Everything in Acts II and III shows up here as one number. | E19: ='Analysis report'!A728 -> ANSWER: EAC at Month 36 is $2,77,85,221 against a BAC of $2,50,00,000 — a projected OVERRUN of $27,85,221 (11.1%). Variance at Completion is -$27,85,221. | F19: Treat EAC vs BAC as the monthly board metric; a recovery plan is due while CPI is 0.90, not when it is 0.80.
A20: ACT IV — THE SQUEEZE: the supply chain sets our programme
A21: 10 | B21: P02 | C21: Materials inflate faster than the contingency | D21: Average material price movement is 7.5%, but RMC M30 (14.8%), Aggregate 20mm (14.6%) and Cement (11.9%) run at double that, and 20 of 90 monthly records exceed 15%. India is the most volatile market (9.8pp std dev). A fixed-price contract priced on a 5% allowance is under-funded before work starts. | E21: ='Analysis report'!A140 -> ANSWER: No material's AVERAGE increase exceeds 15% (highest is RMC M30 at 14.8%), though 20 of 90 individual monthly records are above 15%. Treat the top 3 — RMC M30 (14.8%), Aggregate (20mm) (14.6%), Cement (OPC 53) (11.9%) — as procurement risk and forward-buy / lock rates. | F21: Forward-buy or rate-lock the top 3 movers at award; index-link where the client will accept it.
A22: 11 | B22: P13 | C22: 70% of purchase orders land late | D22: 35 of 50 POs arrive after the expected date, on an average 36.9-day lead time. Copper wiring takes 69 days; vitrified tiles swing between 18 and 74 days (sd 39.6). Not one of the 10 suppliers clears a 90% on-time rate — portfolio on-time performance is 30%. The delay days in Chapter 7 start in this chapter. | E22: ='Analysis report'!A844 -> ANSWER: The scorecard above ranks all 10 suppliers. 0 rate A (90%+ on time), 0 rate B, 0 are watch-list and 10 should be replaced. Portfolio on-time performance is 30.0%. | F22: Dual-source copper and tiles, carry buffer stock, and rebuild the procurement schedule on actual — not quoted — lead times.
A23: ACT V — THE RECKONING: the work is built, the money is not in
A24: 12 | B24: P07 | C24: 2024 closed $7.3m cash-negative | D24: Collected $4.30cr against $5.03cr spent — a $73.2L deficit, with 3 of 4 projects individually negative and the deepest trough in Sep-2024. 17 of 48 project-months collected under 70% of plan, and forecast accuracy is only 76.9%. We are not just collecting badly; we are forecasting badly. | E24: ='Analysis report'!A481 -> ANSWER: At 31-Dec-2024 the portfolio sits at -$73,16,487 cumulative cash. 3 of 4 projects are cash-negative. Best: WT-DC-MUM-01 at $8,39,758; worst: WT-HOS-AKL-03 at -$38,67,202. Collections came in $1,28,96,910 below plan. | F24: Re-forecast cash monthly off actual certification history, and escalate any project-month below 70% of plan within the week.
A25: 13 | B25: P14 | C25: $11.9m outstanding — and most of it is old | D25: $1.19cr remains unpaid on $4.17cr invoiced (71.6% collection). $1.09cr of that is past due and 62.7% of it sits in the 90+ day bucket. Average time to payment is 58 days against ~30-day terms; Brookfield alone holds $41.4L. At 1.5%/month the overdue book has earned $7.98L of claimable interest. | E25: ='Analysis report'!A874 -> ANSWER: Of $1,18,56,858 outstanding, $1,09,01,155 is past due and splits as: $9,98,469 (9.2%) 0–30 days, $30,71,180 (28.2%) 31–60 days, $0 (0.0%) 61–90 days and $68,31,506 (62.7%) 90+ days. The remaining $9,55,703 is not yet due. Average age of past-due debt: 80 days. | F25: Escalate the 90+ bucket to formal recovery and start charging contractual interest — $7.98L is already claimable.
A26: 14 | B26: P15 | C26: The portfolio verdict: amber, and standing still | D26: Of 25 projects, 4 are green, 18 amber and 3 red. 8 are On Hold — tying up $50.6cr of budget doing nothing. 11 projects (44%) sit in the 'late and over cost' quadrant against only 4 true performers. Spend is 48.5% against 49.8% completion, so the portfolio looks on track on paper while the indices say otherwise. | E26: ='Analysis report'!A977 -> ANSWER: The busiest quadrant is "Late and over cost" with 11 of 25 projects (44.0%) and $63,55,84,316 of budget. Only 4 projects are true stars (both indices at or above 1.00). | F26: Force a decision on the 8 on-hold projects (restart or release capital) and put the 3 red projects on recovery plans before taking new work.
A27: 15 | B27: P11 | C27: The missing chapter: risk was never registered | D27: P11 — Risk Register & Probability Matrix — is the one problem of the fifteen with no data sheet in this workbook. That is not a formatting gap, it is the reason the other fourteen chapters read the way they do: the $33.0L of undetermined VOs, the 90+ day debt, the 8 on-hold projects and the 3 red projects are all live risks that nobody scored, owned or priced in advance. Every chapter above is a risk that was managed after it happened. | E27: ="Index lists "&COUNTA(Index!D5:D24)&" problems; 14 have data sheets, P11 (Risk Register) does not. P16-P20 are out of scope for this story." -> Index lists 20 problems; 14 have data sheets, P11 (Risk Register) does not. P16-P20 are out of scope for this story. | F27: Stand up the risk register first: score the exposures already named in Chapters 5, 12, 13 and 14 and give each one an owner and a number.
A29: THE CHAIN, IN ONE LINE
A30: Cheap bid (P05) + drifting rate base (P10) → quantities and variations grow (P01, P03, P08) → site loses 1,467 days to RFIs, suppliers and unstable crews (P04, P06, P09, P13) → materials inflate past the allowance (P02) → EVM confirms 11% overrun (P12) → cash goes negative and debt ages (P07, P14) → portfolio turns amber (P15) — and none of it was ever on a risk register (P11).
A32: THE FIVE MOVES THAT BREAK THE CHAIN
A33: 1. Award on weighted score with a safety/defect hard gate — stop importing the problem at tender (P05, P09).
A34: 2. Re-baseline estimating by country x type and index the top 3 material movers — price the market we are actually in (P10, P02).
A35: 3. Determine the $33.0L VO book within 30 days and remeasure MEP/wet trades monthly — close the leak while it is small (P08, P03, P01).
A36: 4. SLA the RFI turnaround, dual-source the two worst-lead-time materials and fix crew size at the proven band — buy back the 1,467 days (P06, P13, P04, P12).
A37: 5. Re-forecast cash monthly, charge interest on the 90+ bucket and force a restart-or-release call on the 8 on-hold projects (P07, P14, P15, P11).
A39: Sources: every figure traces to the 'Analysis report' sheet (live formulas in column E) and the charts on 'Q&A Chart Dashboard'. Currency shown as in source (Indian digit grouping; cr = crore, L = lakh).

Sheet KPI Dashboard
B1: WT PARTNERSHIP | CONSTRUCTION ANALYTICS DASHBOARD | AB1: CHART DATA — live links to 'Analysis report'. Do not delete; every chart on this dashboard reads from these tables.
AB2: T1 Cost variance by project type (P01 Q2)
B3: Every KPI and chart below is a live formula link to the 'Analysis report' sheet (15 problems, 20 source datasets). Change the source data and this dashboard refreshes automatically. | AB3: Project Type | AC3: Variance %
AB4: ='Analysis report'!A15 -> Residential Tower | AC4: ='Analysis report'!E15 -> 0.26303254
B5: PORTFOLIO BUDGET (USD) | G5: SPEND TO DATE (USD) | L5: AVG PORTFOLIO COMPLETION | Q5: RED-ZONE PROJECTS | AB5: ='Analysis report'!A16 -> IT Park | AC5: ='Analysis report'!E16 -> 0.21567487
B6: ='Analysis report'!B927 -> 1425725823 | G6: ='Analysis report'!D927 -> 690772336 | L6: ='Analysis report'!F928 -> 0.4976 | Q6: ='Analysis report'!B932 -> 3 | AB6: ='Analysis report'!A17 -> University Campus | AC6: ='Analysis report'!E17 -> 0.21727468
B7: =TEXT('Analysis report'!B923,"0")&" live projects | India · Australia · New Zealand" -> 25 live projects | India · Australia · New Zealand | G7: =TEXT('Analysis report'!D927/'Analysis report'!B927,"0.0%")&" of budget drawn" -> 48.5% of budget drawn | L7: ="Avg CPI "&TEXT('Analysis report'!F984,"0.00")&" (target 1.00)" -> Avg CPI 0.93 (target 1.00) | Q7: ="CPI & SPI < 0.90 | "&TEXT('Analysis report'!E990,"$#,##0")&" budget at risk" -> CPI & SPI < 0.90 | $8,75,29,465 budget at risk | AB7: ='Analysis report'!A18 -> Industrial Warehouse | AC7: ='Analysis report'!E18 -> 0.14692435
AB8: ='Analysis report'!A19 -> Data Centre | AC8: ='Analysis report'!E19 -> 0.1216082
B9: PORTFOLIO COST OVERRUN % | G9: PROJECTS OVER BUDGET | L9: TOTAL DELAY DAYS | Q9: NET CASH POSITION (2024) | AB9: ='Analysis report'!A20 -> Hospital | AC9: ='Analysis report'!E20 -> 0.24714839
B10: ='Analysis report'!E25 -> 0.17633728 | G10: ='Analysis report'!C59 -> 0.9 | L10: ='Analysis report'!B462 -> 1467 | Q10: ='Analysis report'!B522 -> -7316487 | AB10: ='Analysis report'!A21 -> Commercial Office | AC10: ='Analysis report'!E21 -> 0.1456331
B11: =TEXT('Analysis report'!D25,"$#,##0")&" over budget on 50 projects" -> $37,95,48,193 over budget on 50 projects | G11: =TEXT('Analysis report'!B59,"0")&" of "&TEXT('Analysis report'!B61,"0")&" projects exceeded budget" -> 45 of 50 projects exceeded budget | L11: ="Cost of delay "&TEXT('Analysis report'!C462,"$#,##0")&" @ $15k/day" -> Cost of delay $2,20,05,000 @ $15k/day | Q11: ="Collection forecast accuracy "&TEXT('Analysis report'!D531,"0.0%") -> Collection forecast accuracy 76.9% | AB11: ='Analysis report'!A22 -> Hotel | AC11: ='Analysis report'!E22 -> 0.13721378
AB12: ='Analysis report'!A23 -> Metro Station | AC12: ='Analysis report'!E23 -> 0.13531167
B13: OUTSTANDING RECEIVABLES | G13: UNRESOLVED VO EXPOSURE | L13: SUPPLIER ON-TIME DELIVERY | Q13: EVM PROJECTED OVERRUN | AB13: ='Analysis report'!A24 -> Shopping Mall | AC13: ='Analysis report'!E24 -> 0.033802807
B14: ='Analysis report'!F848 -> 11856858 | G14: ='Analysis report'!D560 -> 3297152 | L14: =1-'Analysis report'!D816 -> 0.3 | Q14: ='Analysis report'!D727 -> 0.11140886
B15: =TEXT('Analysis report'!C872,"$#,##0")&" of it is 90+ days overdue ("&TEXT('Analysis report'!C872/'Analysis report'!F848,"0.0%")&")" -> $68,31,506 of it is 90+ days overdue (57.6%) | G15: =TEXT('Analysis report'!B560,"0")&" of 45 variations pending / under review" -> 15 of 45 variations pending / under review | L15: =TEXT('Analysis report'!B816,"0")&" of "&TEXT('Analysis report'!F816,"0")&" POs late, avg "&TEXT('Analysis report'!D817,"0.0")&" days" -> 35 of 50 POs late, avg 5.9 days | Q15: ="EAC "&TEXT('Analysis report'!D726,"$#,##0")&" vs BAC "&TEXT('Analysis report'!B726,"$#,##0") -> EAC $2,77,85,221 vs BAC $2,50,00,000 | AB15: T2 Top 5 cost overruns (P01 Q3)
AB16: Project | AC16: Absolute Overrun USD
AB17: ='Analysis report'!C30 -> Residential Tower Per-29 | AC17: ='Analysis report'!E30 -> 24654239
B18: 1. COST & BUDGET PERFORMANCE — where the overrun is coming from | AB18: ='Analysis report'!C31 -> Residential Tower Hyd-33 | AC18: ='Analysis report'!E31 -> 21628203
AB19: ='Analysis report'!C32 -> IT Park Syd-34 | AC19: ='Analysis report'!E32 -> 19739335
AB20: ='Analysis report'!C33 -> University Campus Kol-35 | AC20: ='Analysis report'!E33 -> 19335358
AB21: ='Analysis report'!C34 -> Industrial Warehouse Can-44 | AC21: ='Analysis report'!E34 -> 19116067
AB23: T3 Cost per sqm by country (P10 Q1)
AB24: Country | AC24: Avg Cost per sqm USD
AB25: ='Analysis report'!A652 -> Australia | AC25: ='Analysis report'!B652 -> 3677.1111
AB26: ='Analysis report'!A653 -> India | AC26: ='Analysis report'!B653 -> 670.4
AB27: ='Analysis report'!A654 -> New Zealand | AC27: ='Analysis report'!B654 -> 2993
AB29: T4 Cost overrun by country (P01 Q1)
AB30: Country | AC30: Avg Cost Overrun %
AB31: ='Analysis report'!A8 -> Australia | AC31: ='Analysis report'!B8 -> 0.16732437
AB32: ='Analysis report'!A9 -> India | AC32: ='Analysis report'!B9 -> 0.15763933
AB33: ='Analysis report'!A10 -> New Zealand | AC33: ='Analysis report'!B10 -> 0.19747604
AB35: T5 Delay cause Pareto (P06 Q1)
AB36: Delay Cause | AC36: Events | AD36: Cumulative %
AB37: ='Analysis report'!B387 -> RFI Response Delay | AC37: ='Analysis report'!C387 -> 11 | AD37: ='Analysis report'!E387 -> 0.18333333
AB38: ='Analysis report'!B388 -> Permit Delay | AC38: ='Analysis report'!C388 -> 8 | AD38: ='Analysis report'!E388 -> 0.31666667
B39: 2. GEOGRAPHY — cost levels and overrun by country | AB39: ='Analysis report'!B389 -> Material Delay | AC39: ='Analysis report'!C389 -> 8 | AD39: ='Analysis report'!E389 -> 0.45
AB40: ='Analysis report'!B390 -> Client Decision Pending | AC40: ='Analysis report'!C390 -> 6 | AD40: ='Analysis report'!E390 -> 0.55
AB41: ='Analysis report'!B391 -> Labour Shortage | AC41: ='Analysis report'!C391 -> 5 | AD41: ='Analysis report'!E391 -> 0.63333333
AB42: ='Analysis report'!B392 -> Equipment Breakdown | AC42: ='Analysis report'!C392 -> 5 | AD42: ='Analysis report'!E392 -> 0.71666667
AB43: ='Analysis report'!B393 -> Rework | AC43: ='Analysis report'!C393 -> 5 | AD43: ='Analysis report'!E393 -> 0.8
...

Sheet P01-CostOverrun
A1: c
A2: Scenario: WT manages 50 projects across India, Australia & NZ. Analyse which projects exceeded budget and why.
A4: Project_ID | B4: Project_Name | C4: City | D4: Country | E4: Type | F4: Budgeted_Cost_USD | G4: Actual_Cost_USD | H4: Duration_Months | I4: Variance_USD | J4: Variance_% | K4: Absolute_Variance_USD
A5: WT-1028 | B5: Residential Tower Per-29 | C5: Perth | D5: Australia | E5: Residential Tower | F5: 74394227 | G5: 99048466 | H5: 39 | I5: =G5-F5 -> 24654239 | J5: =I5/F5 -> 0.33139989 | K5: =ABS(I5) -> 24654239
A6: WT-1032 | B6: Residential Tower Hyd-33 | C6: Hyderabad | D6: India | E6: Residential Tower | F6: 65791320 | G6: 87419523 | H6: 16 | I6: =G6-F6 -> 21628203 | J6: =I6/F6 -> 0.32873946 | K6: =ABS(I6) -> 21628203
A7: WT-1033 | B7: IT Park Syd-34 | C7: Sydney | D7: Australia | E7: IT Park | F7: 58792612 | G7: 78531947 | H7: 40 | I7: =G7-F7 -> 19739335 | J7: =I7/F7 -> 0.33574516 | K7: =ABS(I7) -> 19739335
A8: WT-1034 | B8: University Campus Kol-35 | C8: Kolkata | D8: India | E8: University Campus | F8: 55551839 | G8: 74887197 | H8: 47 | I8: =G8-F8 -> 19335358 | J8: =I8/F8 -> 0.34805973 | K8: =ABS(I8) -> 19335358
A9: WT-1043 | B9: Industrial Warehouse Can-44 | C9: Canberra | D9: Australia | E9: Industrial Warehouse | F9: 64682989 | G9: 83799056 | H9: 9 | I9: =G9-F9 -> 19116067 | J9: =I9/F9 -> 0.29553469 | K9: =ABS(I9) -> 19116067
A10: WT-1031 | B10: Data Centre Del-32 | C10: Delhi | D10: India | E10: Data Centre | F10: 67228535 | G10: 85811127 | H10: 40 | I10: =G10-F10 -> 18582592 | J10: =I10/F10 -> 0.2764093 | K10: =ABS(I10) -> 18582592
A11: WT-1024 | B11: Data Centre Mum-25 | C11: Mumbai | D11: India | E11: Data Centre | F11: 74070937 | G11: 92614679 | H11: 47 | I11: =G11-F11 -> 18543742 | J11: =I11/F11 -> 0.25035112 | K11: =ABS(I11) -> 18543742
A12: WT-1026 | B12: University Campus Mum-27 | C12: Mumbai | D12: India | E12: University Campus | F12: 69187530 | G12: 86815466 | H12: 38 | I12: =G12-F12 -> 17627936 | J12: =I12/F12 -> 0.25478487 | K12: =ABS(I12) -> 17627936
A13: WT-1049 | B13: Hospital Auc-50 | C13: Auckland | D13: New Zealand | E13: Hospital | F13: 55826716 | G13: 73187548 | H13: 16 | I13: =G13-F13 -> 17360832 | J13: =I13/F13 -> 0.31097713 | K13: =ABS(I13) -> 17360832
A14: WT-1027 | B14: University Campus Che-28 | C14: Chennai | D14: India | E14: University Campus | F14: 70137358 | G14: 83715114 | H14: 15 | I14: =G14-F14 -> 13577756 | J14: =I14/F14 -> 0.19358807 | K14: =ABS(I14) -> 13577756
A15: WT-1044 | B15: Commercial Office Che-45 | C15: Chennai | D15: India | E15: Commercial Office | F15: 56038913 | G15: 69560286 | H15: 12 | I15: =G15-F15 -> 13521373 | J15: =I15/F15 -> 0.24128543 | K15: =ABS(I15) -> 13521373
A16: WT-1015 | B16: Hospital Chr-16 | C16: Christchurch | D16: New Zealand | E16: Hospital | F16: 45524491 | G16: 58596428 | H16: 9 | I16: =G16-F16 -> 13071937 | J16: =I16/F16 -> 0.28714076 | K16: =ABS(I16) -> 13071937
... A54: WT-1047 | B54: IT Park Gol-48 | C54: Gold Coast | D54: Australia | E54: IT Park | F54: 15141087 | G54: 14690417 | H54: 40 | I54: =G54-F54 -> -450670 | J54: =I54/F54 -> -0.029764706 | K54: =ABS(I54) -> 450670
A56: ANALYSIS QUESTIONS
A57: Q1. Which country has the highest average cost overrun percentage?
A58: Q2. What is the total budget vs actual cost for each project type? Which type has the worst variance?
A59: Q3. Identify the Top 5 projects with the highest absolute cost overrun (in USD).
A60: Q4. Is there a correlation between project duration and cost overrun percentage?
A61: Q5. Create a pivot table showing average overrun % by Country × Project Type.
A62: Q6. What percentage of projects came in under budget vs over budget?
A63: Q7. Which city has the most cost-efficient project delivery?

Sheet P01
A1: Cost Over Run Analysis
A4: Q1
A7: Country | B7: Average of Variance_%
A8: Australia | B8: 0.16732437
A9: India | B9: 0.15763933
A10: New Zealand | B10: 0.19747604
A11: Grand Total | B11: 0.16612198
A13: The Country with the highest average cost overrun percentage is Newzealand, with an average overrun of 19.75%
A15: Q2
A18: Project Type | B18: Total Budget | C18: Actual Cost | D18: Total Variance | E18: Average of Variance_%
A19: Commercial Office | B19: 139292114 | C19: 159577657 | D19: 20285543 | E19: 0.13323602
A20: Data Centre | B20: 377404871 | C20: 423300399 | D20: 45895528 | E20: 0.10730588
A21: Hospital | B21: 202218749 | C21: 252196787 | D21: 49978038 | E21: 0.25210129
A22: Hotel | B22: 276402274 | C22: 314328476 | D22: 37926202 | E22: 0.13762155
A23: Industrial Warehouse | B23: 162936980 | C23: 186876390 | D23: 23939410 | E23: 0.1314705
A24: IT Park | B24: 207257585 | C24: 251957838 | D24: 44700253 | E24: 0.18258894
A25: Metro Station | B25: 194389591 | C25: 220692772 | D25: 26303181 | E25: 0.15213723
A26: Residential Tower | B26: 238232594 | C26: 300895518 | D26: 62662924 | E26: 0.24593854
A27: Shopping Mall | B27: 49683626 | C27: 51363072 | D27: 1679446 | E27: 0.033802807
A28: University Campus | B28: 304580669 | C28: 370758337 | D28: 66177668 | E28: 0.21100059
A29: Grand Total | B29: 2152399053 | C29: 2531947246 | D29: 379548193 | E29: 0.16612198
A31: Hospital has the worst variance percentage with an average cost overrun of 25.21%. But university campus has the highest total cost variance at USD 66,177,668.
A34: Q3
A37: Residential Tower Per-29
A38: Residential Tower Hyd-33 | B38: This Five project are having highest absolute cost over run variance in USD, this found by sorting and highlighted via conditional formatting of top 5.
A39: IT Park Syd-34
A40: University Campus Kol-35
A41: Industrial Warehouse Can-44
A43: Q4
A46: =CORREL('P01-CostOverrun'!H5:H54,'P01-CostOverrun'!J5:J54) -> -0.15637931
A48: There is a weak negative correlation (-0.156) between project duration and cost overrun percentage. This suggests that longer project durations are slightly associated with lower cost overrun percentages in this dataset. However, the relationship is very weak and does not establish causation.
A52: Q5
A55: Average of Variance_% | B55: Column Labels
A56: Row Labels | B56: Commercial Office | C56: Data Centre | D56: Hospital | E56: Hotel | F56: Industrial Warehouse | G56: IT Park | H56: Metro Station | I56: Residential Tower | J56: Shopping Mall | K56: University Campus | L56: Grand Total
A57: Australia | C57: 0.11293848 | D57: 0.18570627 | E57: 0.22210857 | F57: 0.29553469 | G57: 0.15299023 | H57: 0.09327325 | I57: 0.23322555 | K57: 0.088721909 | L57: 0.16732437
A58: India | B58: 0.13323602 | C58: 0.12639265 | D58: 0.23834115 | E58: 0.074256278 | F58: 0.061148534 | G58: 0.18083416 | H58: 0.057979113 | I58: 0.25865153 | J58: 0.033802807 | K58: 0.27213993 | L58: 0.15763933
A59: New Zealand | C59: -0.018479937 | D59: 0.29905895 | F59: 0.037728288 | G59: 0.24880551 | H59: 0.25808028 | L59: 0.19747604
A60: Grand Total | B60: 0.13323602 | C60: 0.10730588 | D60: 0.25210129 | E60: 0.13762155 | F60: 0.1314705 | G60: 0.18258894 | H60: 0.15213723 | I60: 0.24593854 | J60: 0.033802807 | K60: 0.21100059 | L60: 0.16612198
A62: New Zealand has the highest overall average cost overrun (19.75%). Hospital projects in New Zealand show the highest country-type average (29.91%).
A65: Q6
...

Sheet P02-MaterialPrice
A1: PROBLEM 2: Material Price Fluctuation Tracker
A2: Scenario: Track monthly prices of 15 key construction materials over 18 months to forecast procurement budgets.
A4: Month | B4: Material | C4: Unit | D4: Base_Price_USD | E4: Current_Price_USD | F4: Supplier_City | G4: Country | H4: Price_Change_% | I4: Procurement Risk
A5: 2024-04 | B5: Waterproofing Membrane | C5: sqm | D5: 15 | E5: 18.73 | F5: Delhi | G5: India | H5: =(E5-D5)/D5 -> 0.24866667 | I5: =IF(H5>15%,"high risk", "Normal") -> high risk
A6: 2024-09 | B6: Cement (OPC 53) | C6: MT | D6: 85 | E6: 105.52 | F6: Hyderabad | G6: India | H6: =(E6-D6)/D6 -> 0.24141176 | I6: =IF(H6>15%,"high risk", "Normal") -> high risk
A7: 2025-01 | B7: Aluminium Facade | C7: sqm | D7: 120 | E7: 147.98 | F7: Brisbane | G7: Australia | H7: =(E7-D7)/D7 -> 0.23316667 | I7: =IF(H7>15%,"high risk", "Normal") -> high risk
A8: 2024-03 | B8: Bricks (AAC) | C8: 1000 nos | D8: 380 | E8: 467.68 | F8: Hamilton | G8: New Zealand | H8: =(E8-D8)/D8 -> 0.23073684 | I8: =IF(H8>15%,"high risk", "Normal") -> high risk
A9: 2024-05 | B9: Tiles (Vitrified) | C9: sqm | D9: 18 | E9: 22.1 | F9: Delhi | G9: India | H9: =(E9-D9)/D9 -> 0.22777778 | I9: =IF(H9>15%,"high risk", "Normal") -> high risk
A10: 2024-09 | B10: PVC Conduits | C10: m | D10: 3 | E10: 3.68 | F10: Ahmedabad | G10: India | H10: =(E10-D10)/D10 -> 0.22666667 | I10: =IF(H10>15%,"high risk", "Normal") -> high risk
A11: 2024-02 | B11: Sand (River) | C11: cum | D11: 25 | E11: 30.58 | F11: Wellington | G11: New Zealand | H11: =(E11-D11)/D11 -> 0.2232 | I11: =IF(H11>15%,"high risk", "Normal") -> high risk
A12: 2024-05 | B12: Structural Steel | C12: MT | D12: 950 | E12: 1149.65 | F12: Perth | G12: Australia | H12: =(E12-D12)/D12 -> 0.21015789 | I12: =IF(H12>15%,"high risk", "Normal") -> high risk
A13: 2024-11 | B13: Aggregate (20mm) | C13: cum | D13: 22 | E13: 26.52 | F13: Sydney | G13: Australia | H13: =(E13-D13)/D13 -> 0.20545455 | I13: =IF(H13>15%,"high risk", "Normal") -> high risk
A14: 2025-05 | B14: Cement (OPC 53) | C14: MT | D14: 85 | E14: 102.04 | F14: Delhi | G14: India | H14: =(E14-D14)/D14 -> 0.20047059 | I14: =IF(H14>15%,"high risk", "Normal") -> high risk
A15: 2024-05 | B15: Aluminium Facade | C15: sqm | D15: 120 | E15: 143.42 | F15: Melbourne | G15: Australia | H15: =(E15-D15)/D15 -> 0.19516667 | I15: =IF(H15>15%,"high risk", "Normal") -> high risk
A16: 2025-03 | B16: MS Pipes | C16: m | D16: 12 | E16: 14.34 | F16: Melbourne | G16: Australia | H16: =(E16-D16)/D16 -> 0.195 | I16: =IF(H16>15%,"high risk", "Normal") -> high risk
... A94: 2025-01 | B94: Glass (DGU) | C94: sqm | D94: 95 | E94: 87.45 | F94: Christchurch | G94: New Zealand | H94: =(E94-D94)/D94 -> -0.079473684 | I94: =IF(H94>15%,"high risk", "Normal") -> Normal
A96: ANALYSIS QUESTIONS
A97: Q1. Which material has shown the highest average price increase over 18 months?
A98: Q2. Create a line chart showing monthly price trend for TMT Steel and Cement.
A99: Q3. Which country has the most volatile material pricing? (Use standard deviation)
A100: Q4. Identify the top 3 materials with price increase > 15% — flag them as procurement risk.
A101: Q5. What is the average price change % by material across all months?
A102: Q6. If WT needs 500 MT of steel next quarter, what is the projected cost based on the trend?

Sheet P02
A1: Material Price Fluctuation
A4: Q1
A7: Materials | B7: Average of Price_Change_%
A8: Aggregate (20mm) | B8: 0.14609091
A9: Aluminium Facade | B9: 0.11697917
A10: Bricks (AAC) | B10: 0.077399123
A11: Cement (OPC 53) | B11: 0.11856863
A12: Copper Wiring | B12: 0.01925
A13: Glass (DGU) | B13: 0.043934211 | C13: RMC M30 has shown the highest average price increase over the 18 month period, with an average price increase of 14.78%.
A14: MS Pipes | B14: 0.099375
A15: Plywood (Marine) | B15: 0.092555556
A16: PVC Conduits | B16: 0.030416667
A17: RMC M30 | B17: 0.1478
A18: Sand (River) | B18: 0.0952
A19: Structural Steel | B19: 0.069677193
A20: Tiles (Vitrified) | B20: 0.083611111
A21: TMT Steel (Fe500) | B21: 0.039138462
A22: Waterproofing Membrane | B22: 0.0252
A23: Grand Total | B23: 0.075402982
A26: Q2
A29: Average of Current_Price_USD | B29: Material Filter
A30: Month timeline | B30: Cement (OPC 53) | C30: TMT Steel (Fe500) | D30: Grand Total
A31: 2024-01 | B31: 96.77 | C31: 1 | D31: 96.77
A32: 2024-02 | B32: 94.59 | C32: 1 | D32: 94.59
A33: 2024-03 | B33: 1 | C33: 710.14 | D33: 710.14
A34: 2024-06 | B34: 81.11 | C34: 1 | D34: 81.11
A35: 2024-09 | B35: 105.52 | C35: 1 | D35: 105.52
A36: 2024-12 | B36: 90.44 | C36: 1 | D36: 90.44
A37: 2025-01 | B37: 1 | C37: 607.52 | D37: 607.52
A38: 2025-02 | B38: 1 | C38: 688.19 | D38: 688.19 | E38: The line chart illustrates the monthly price trends of TMT Steel and Cement over the 18-month period. It helps identify price fluctuations and changes in procurement costs over time.
A39: 2025-05 | B39: 102.04 | C39: 1 | D39: 102.04
A40: 2025-06 | B40: 1 | C40: 695.91 | D40: 695.91
A41: Grand Total | B41: 95.078333 | C41: 675.44 | D41: 327.223
A59: Q3
A62: Country | B62: StdDev of Price_Change_%
A63: Australia | B63: 0.092102807 | C63: India has the most volatile material prices, with a standard deviation of 9.79%, indicating greater fluctuations in price changes compared to other countries.
A64: India | B64: 0.097922415
A65: New Zealand | B65: 0.089924746
A66: Grand Total | B66: 0.093298287
A68: Q4
...

Sheet P03-BOQVariance
A1: PROBLEM 3: BOQ (Bill of Quantities) Variance Analysis
A2: Scenario: Compare original BOQ quantities vs actual measured quantities for 3 projects across 20 trade items each.
A4: Project_ID | B4: Trade | C4: BOQ_Item | D4: Unit | E4: BOQ_Qty | F4: Actual_Qty | G4: Rate_USD | H4: BOQ_Amount_USD | I4: Actual_Amount_USD | J4: Qty_Variance | K4: Qty_Variance_% | L4: Qty_Status | M4: Overrun_Imapact_USD
A5: WT-HOS-AKL-03 | B5: Civil & Structure | C5: Plastering | D5: rmt | E5: 4879 | F5: 6291 | G5: 107.3 | H5: 523516.7 | I5: =F5*G5 -> 675024.3 | J5: =F5-E5 -> 1412 | K5: =J5/E5 -> 0.28940357 | L5: =IF(F5>E5,"Over BOQ","Within BOQ") -> Over BOQ | M5: =IF(J5>0,J5*G5,0) -> 151507.6
A6: WT-OFF-SYD-02 | B6: MEP - Electrical | C6: LT Panels | D6: set | E6: 4324 | F6: 5554 | G6: 57.67 | H6: 249365.08 | I6: =F6*G6 -> 320299.18 | J6: =F6-E6 -> 1230 | K6: =J6/E6 -> 0.28445883 | L6: =IF(F6>E6,"Over BOQ","Within BOQ") -> Over BOQ | M6: =IF(J6>0,J6*G6,0) -> 70934.1
A7: WT-DC-MUM-01 | B7: Civil & Structure | C7: Excavation | D7: kg | E7: 2649 | F7: 3384 | G7: 178.83 | H7: 473720.67 | I7: =F7*G7 -> 605160.72 | J7: =F7-E7 -> 735 | K7: =J7/E7 -> 0.27746319 | L7: =IF(F7>E7,"Over BOQ","Within BOQ") -> Over BOQ | M7: =IF(J7>0,J7*G7,0) -> 131440.05
A8: WT-HOS-AKL-03 | B8: MEP - Electrical | C8: Conduit Laying | D8: sqm | E8: 4660 | F8: 5951 | G8: 21.61 | H8: 100702.6 | I8: =F8*G8 -> 128601.11 | J8: =F8-E8 -> 1291 | K8: =J8/E8 -> 0.27703863 | L8: =IF(F8>E8,"Over BOQ","Within BOQ") -> Over BOQ | M8: =IF(J8>0,J8*G8,0) -> 27898.51
A9: WT-HOS-AKL-03 | B9: Interior Fit-out | C9: False Ceiling | D9: set | E9: 862 | F9: 1100 | G9: 45.52 | H9: 39238.24 | I9: =F9*G9 -> 50072 | J9: =F9-E9 -> 238 | K9: =J9/E9 -> 0.27610209 | L9: =IF(F9>E9,"Over BOQ","Within BOQ") -> Over BOQ | M9: =IF(J9>0,J9*G9,0) -> 10833.76
A10: WT-OFF-SYD-02 | B10: MEP - Plumbing | C10: CPVC Piping | D10: cum | E10: 2334 | F10: 2909 | G10: 52.55 | H10: 122651.7 | I10: =F10*G10 -> 152867.95 | J10: =F10-E10 -> 575 | K10: =J10/E10 -> 0.24635818 | L10: =IF(F10>E10,"Over BOQ","Within BOQ") -> Over BOQ | M10: =IF(J10>0,J10*G10,0) -> 30216.25
A11: WT-HOS-AKL-03 | B11: MEP - Plumbing | C11: Sanitary Fixtures | D11: nos | E11: 2485 | F11: 3074 | G11: 198.06 | H11: 492179.1 | I11: =F11*G11 -> 608836.44 | J11: =F11-E11 -> 589 | K11: =J11/E11 -> 0.23702213 | L11: =IF(F11>E11,"Over BOQ","Within BOQ") -> Over BOQ | M11: =IF(J11>0,J11*G11,0) -> 116657.34
A12: WT-DC-MUM-01 | B12: MEP - Electrical | C12: Cable Trays | D12: set | E12: 210 | F12: 259 | G12: 154.29 | H12: 32400.9 | I12: =F12*G12 -> 39961.11 | J12: =F12-E12 -> 49 | K12: =J12/E12 -> 0.23333333 | L12: =IF(F12>E12,"Over BOQ","Within BOQ") -> Over BOQ | M12: =IF(J12>0,J12*G12,0) -> 7560.21
A13: WT-OFF-SYD-02 | B13: MEP - Plumbing | C13: Sanitary Fixtures | D13: cum | E13: 4099 | F13: 5053 | G13: 40.46 | H13: 165845.54 | I13: =F13*G13 -> 204444.38 | J13: =F13-E13 -> 954 | K13: =J13/E13 -> 0.23273969 | L13: =IF(F13>E13,"Over BOQ","Within BOQ") -> Over BOQ | M13: =IF(J13>0,J13*G13,0) -> 38598.84
A14: WT-OFF-SYD-02 | B14: MEP - HVAC | C14: Ductwork | D14: cum | E14: 2520 | F14: 3106 | G14: 122.08 | H14: 307641.6 | I14: =F14*G14 -> 379180.48 | J14: =F14-E14 -> 586 | K14: =J14/E14 -> 0.23253968 | L14: =IF(F14>E14,"Over BOQ","Within BOQ") -> Over BOQ | M14: =IF(J14>0,J14*G14,0) -> 71538.88
A15: WT-DC-MUM-01 | B15: MEP - Plumbing | C15: CPVC Piping | D15: nos | E15: 1402 | F15: 1721 | G15: 184.31 | H15: 258402.62 | I15: =F15*G15 -> 317197.51 | J15: =F15-E15 -> 319 | K15: =J15/E15 -> 0.2275321 | L15: =IF(F15>E15,"Over BOQ","Within BOQ") -> Over BOQ | M15: =IF(J15>0,J15*G15,0) -> 58794.89
A16: WT-DC-MUM-01 | B16: Civil & Structure | C16: RCC Slabs | D16: rmt | E16: 2075 | F16: 2547 | G16: 59.08 | H16: 122591 | I16: =F16*G16 -> 150476.76 | J16: =F16-E16 -> 472 | K16: =J16/E16 -> 0.22746988 | L16: =IF(F16>E16,"Over BOQ","Within BOQ") -> Over BOQ | M16: =IF(J16>0,J16*G16,0) -> 27885.76
... A76: WT-DC-MUM-01 | B76: MEP - Electrical | C76: HT Cables | D76: nos | E76: 3957 | F76: 3373 | G76: 73.59 | H76: 291195.63 | I76: =F76*G76 -> 248219.07 | J76: =F76-E76 -> -584 | K76: =J76/E76 -> -0.14758656 | L76: =IF(F76>E76,"Over BOQ","Within BOQ") -> Within BOQ | M76: =IF(J76>0,J76*G76,0) -> 0
A78: ANALYSIS QUESTIONS
A79: Q1. Which project has the highest total BOQ variance (in USD)? | G79: PCC in civil structure has the highest BOQ variance in USD
A80: Q2. Which trade consistently exceeds BOQ quantities across all 3 projects?
A81: Q3. Identify the top 5 BOQ items with the highest quantity variance %.
A82: Q4. What is the total financial impact of quantity overruns per project?
A83: Q5. Create a waterfall chart showing BOQ Amount vs Actual Amount per trade for Project WT-DC-MUM-01.
A84: Q6. Which items have negative variance (came under BOQ)? What's the saving?
D99: ='P03'!D61-'P03'!B62 -> 375655.02

Sheet P03
A1: BOQ Variance Analysis
A4: Q1
A7: Project ID | B7: Sum of BOQ_Amount_USD | C7: Sum of Actual_Amount_USD | D7: Total Variance (USD)
A8: WT-DC-MUM-01 | B8: 5686239.8 | C8: 6061894.8 | D8: =C8-B8 -> 375655.02
A9: WT-HOS-AKL-03 | B9: 4619527.9 | C9: 5117552.2 | D9: =C9-B9 -> 498024.35
A10: WT-OFF-SYD-02 | B10: 5691799.9 | C10: 6408709.9 | D10: =C10-B10 -> 716909.95
A11: Grand Total | B11: 15997568 | C11: 17588157 | D11: =C11-B11 -> 1590589.3
A13: Project ID WT-DC-MUM-01 has the highest BOQ Variance
A16: Q2
A19: Sum of Qty_Variance | B19: Project ID
A20: Row Labels | B20: WT-DC-MUM-01 | C20: WT-HOS-AKL-03 | D20: WT-OFF-SYD-02 | E20: Grand Total
A21: Civil & Structure | B21: 2054 | C21: 1150 | D21: 937 | E21: 4141
A22: Interior Fit-out | B22: 397 | C22: 727 | D22: 1834 | E22: 2958
A23: MEP - Electrical | B23: -78 | C23: 1968 | D23: 2865 | E23: 4755
A24: MEP - HVAC | B24: 502 | C24: 24 | D24: 1952 | E24: 2478
A25: MEP - Plumbing | B25: -519 | C25: 1678 | D25: 2734 | E25: 3893
A26: Grand Total | B26: 2356 | C26: 5547 | D26: 10322 | E26: 18225
A28: Civil & Structure, Interior Fit-Out, and MEP - HVAC consistently exceeded BOQ quantities across all three projects, recording positive quantity variances in each project.
A32: Q3
A35: BOQ_Item | B35: Qty_Variance_%
A36: Plastering | B36: 0.28940357 | C36: The top 5 BOQ items with the highest quantity variance percentages were identified by sorting the quantity variance percentage in descending order.
A37: LT Panels | B37: 0.28445883
A38: Excavation | B38: 0.27746319
A39: Conduit Laying | B39: 0.27703863
A40: False Ceiling | B40: 0.27610209
A42: Q4
A45: Project ID | B45: Sum of Overrun_Imapact_USD
A46: WT-DC-MUM-01 | B46: 502032.7 | C46: The total financial impact of quantity overruns across all three projects is $1,828,491.49. WT-OFF-SYD-02 had the highest overrun impact at $768,547.75, followed by WT-HOS-AKL-03 at $557,911.04 and WT-DC-MUM-01 at $502,032.70.
A47: WT-HOS-AKL-03 | B47: 557911.04
A48: WT-OFF-SYD-02 | B48: 768547.75
A49: Grand Total | B49: 1828491.5
A51: Q5
A55: Trade | B55: BOQ Amount | C55: variance | D55: Actual Amount | F55: Category | G55: Amount
A56: {=_xlfn.UNIQUE('P03-BOQVariance'!B5:B76)} -> Civil & Structure | B56: =SUMIFS('P03-BOQVariance'!$H:$H,'P03-BOQVariance'!$A:$A,"WT-DC-MUM-01",'P03-BOQVariance'!$B:$B,A56) -> 1893094.3 | C56: =SUMIFS('P03-BOQVariance'!$I:$I,'P03-BOQVariance'!$A:$A,"WT-DC-MUM-01",'P03-BOQVariance'!$B:$B,A56)-B56 -> 238929.32 | D56: =SUMIFS('P03-BOQVariance'!$I:$I,'P03-BOQVariance'!$A:$A,"WT-DC-MUM-01",'P03-BOQVariance'!$B:$B,A56) -> 2132023.6 | F56: =A56 -> Civil & Structure | G56: =C56 -> 238929.32
A57: MEP - Electrical | B57: =SUMIFS('P03-BOQVariance'!$H:$H,'P03-BOQVariance'!$A:$A,"WT-DC-MUM-01",'P03-BOQVariance'!$B:$B,A57) -> 986727.76 | C57: =SUMIFS('P03-BOQVariance'!$I:$I,'P03-BOQVariance'!$A:$A,"WT-DC-MUM-01",'P03-BOQVariance'!$B:$B,A57)-B57 -> 20630.29 | D57: =SUMIFS('P03-BOQVariance'!$I:$I,'P03-BOQVariance'!$A:$A,"WT-DC-MUM-01",'P03-BOQVariance'!$B:$B,A57) -> 1007358.1 | F57: =A57 -> MEP - Electrical | G57: =C57 -> 20630.29
A58: Interior Fit-out | B58: =SUMIFS('P03-BOQVariance'!$H:$H,'P03-BOQVariance'!$A:$A,"WT-DC-MUM-01",'P03-BOQVariance'!$B:$B,A58) -> 1202994.9 | C58: =SUMIFS('P03-BOQVariance'!$I:$I,'P03-BOQVariance'!$A:$A,"WT-DC-MUM-01",'P03-BOQVariance'!$B:$B,A58)-B58 -> 88907.45 | D58: =SUMIFS('P03-BOQVariance'!$I:$I,'P03-BOQVariance'!$A:$A,"WT-DC-MUM-01",'P03-BOQVariance'!$B:$B,A58) -> 1291902.4 | F58: =A58 -> Interior Fit-out | G58: =C58 -> 88907.45
A59: MEP - Plumbing | B59: =SUMIFS('P03-BOQVariance'!$H:$H,'P03-BOQVariance'!$A:$A,"WT-DC-MUM-01",'P03-BOQVariance'!$B:$B,A59) -> 765988.47 | C59: =SUMIFS('P03-BOQVariance'!$I:$I,'P03-BOQVariance'!$A:$A,"WT-DC-MUM-01",'P03-BOQVariance'!$B:$B,A59)-B59 -> -9419.5 | D59: =SUMIFS('P03-BOQVariance'!$I:$I,'P03-BOQVariance'!$A:$A,"WT-DC-MUM-01",'P03-BOQVariance'!$B:$B,A59) -> 756568.97 | F59: =A59 -> MEP - Plumbing | G59: =C59 -> -9419.5
A60: MEP - HVAC | B60: =SUMIFS('P03-BOQVariance'!$H:$H,'P03-BOQVariance'!$A:$A,"WT-DC-MUM-01",'P03-BOQVariance'!$B:$B,A60) -> 837434.33 | C60: =SUMIFS('P03-BOQVariance'!$I:$I,'P03-BOQVariance'!$A:$A,"WT-DC-MUM-01",'P03-BOQVariance'!$B:$B,A60)-B60 -> 36607.46 | D60: =SUMIFS('P03-BOQVariance'!$I:$I,'P03-BOQVariance'!$A:$A,"WT-DC-MUM-01",'P03-BOQVariance'!$B:$B,A60) -> 874041.79 | F60: =A60 -> MEP - HVAC | G60: =C60 -> 36607.46
A61: Actual Total | D61: =SUMIFS('P03-BOQVariance'!$I:$I,'P03-BOQVariance'!$A:$A,"WT-DC-MUM-01") -> 6061894.8 | F61: =A61 -> Actual Total | G61: =D61 -> 6061894.8
A62: BOQ baseline | B62: =SUMIFS('P03-BOQVariance'!$H:$H,'P03-BOQVariance'!$A:$A,"WT-DC-MUM-01") -> 5686239.8 | F62: =A62 -> BOQ baseline | G62: =B62 -> 5686239.8

Sheet P04-LabourProd
A1: PROBLEM 4: Labour Productivity by Trade
A2: Scenario: Track daily output of workers across trades to identify low-productivity areas.
A4: Date | B4: Project_ID | C4: Trade | D4: Workers_Count | E4: Hours_Worked | F4: Output_Qty | G4: Output_Unit | H4: City | I4: Productivity_per_ManHour
A5: 2025-03-01 | B5: WT-HOS-AKL-03 | C5: Facade & Cladding | D5: 17 | E5: 7.7 | F5: 470.6 | G5: cum | H5: Hyderabad | I5: =F5/(D5*E5) -> 3.5951108
A6: 2025-02-06 | B6: WT-DC-MUM-01 | C6: Civil & Structure | D6: 15 | E6: 9.2 | F6: 452.4 | G6: rmt | H6: Ahmedabad | I6: =F6/(D6*E6) -> 3.2782609
A7: 2025-02-01 | B7: WT-ITP-BLR-04 | C7: Facade & Cladding | D7: 24 | E7: 8.8 | F7: 1132.6 | G7: nos | H7: Ahmedabad | I7: =F7/(D7*E7) -> 5.3626894
A8: 2025-01-21 | B8: WT-DC-MUM-01 | C8: MEP - Plumbing | D8: 25 | E8: 8.4 | F8: 56.7 | G8: cum | H8: Mumbai | I8: =F8/(D8*E8) -> 0.27
A9: 2025-03-10 | B9: WT-DC-MUM-01 | C9: MEP - HVAC | D9: 35 | E9: 8.1 | F9: 793.4 | G9: rmt | H9: Delhi | I9: =F9/(D9*E9) -> 2.7985891
A10: 2025-05-30 | B10: WT-ITP-BLR-04 | C10: Facade & Cladding | D10: 36 | E10: 9.9 | F10: 865.1 | G10: nos | H10: Pune | I10: =F10/(D10*E10) -> 2.4273288
A11: 2025-03-24 | B11: WT-DC-MUM-01 | C11: MEP - HVAC | D11: 26 | E11: 7.6 | F11: 657.2 | G11: nos | H11: Mumbai | I11: =F11/(D11*E11) -> 3.3259109
A12: 2025-04-27 | B12: WT-DC-MUM-01 | C12: MEP - Electrical | D12: 21 | E12: 7.3 | F12: 1019.3 | G12: nos | H12: Mumbai | I12: =F12/(D12*E12) -> 6.6490541
A13: 2025-05-19 | B13: WT-ITP-BLR-04 | C13: MEP - Plumbing | D13: 8 | E13: 6.8 | F13: 149.8 | G13: nos | H13: Ahmedabad | I13: =F13/(D13*E13) -> 2.7536765
A14: 2025-01-14 | B14: WT-OFF-SYD-02 | C14: MEP - Electrical | D14: 40 | E14: 6.5 | F14: 604.5 | G14: nos | H14: Bangalore | I14: =F14/(D14*E14) -> 2.325
A15: 2025-01-08 | B15: WT-OFF-SYD-02 | C15: Facade & Cladding | D15: 15 | E15: 7.2 | F15: 25.1 | G15: nos | H15: Bangalore | I15: =F15/(D15*E15) -> 0.23240741
A16: 2025-02-27 | B16: WT-DC-MUM-01 | C16: MEP - Plumbing | D16: 12 | E16: 8.6 | F16: 102.5 | G16: rmt | H16: Hyderabad | I16: =F16/(D16*E16) -> 0.99321705
... A84: 2025-01-22 | B84: WT-HOS-AKL-03 | C84: Interior Fit-out | D84: 29 | E84: 8.6 | F84: 495.8 | G84: cum | H84: Bangalore | I84: =F84/(D84*E84) -> 1.9879711
A86: ANALYSIS QUESTIONS
A87: Q1. Which trade has the highest average productivity per man-hour?
A88: Q2. Is there a productivity difference between projects in India vs Australia?
A89: Q3. Create a box plot (or summary stats) of productivity by trade — which has the most variance?
A90: Q4. On which dates did productivity drop below the 25th percentile? What was the trade?
A91: Q5. What is the optimal crew size (workers count) that maximises productivity for Civil & Structure?
A92: Q6. Calculate total man-hours consumed per project and rank them.

Sheet P05-TenderBid
A1: PROBLEM 5: Tender Bid Comparison Analysis
A2: Scenario: WT received bids from multiple contractors for 5 trade packages. Evaluate and rank.
A4: Tender_Package | B4: Contractor | C4: Bid_Amount_USD | D4: Completion_Days | E4: Experience_Years | F4: Safety_Rating | G4: Past_Defect_Rate_% | H4: Financial_Score
A5: Structural Works | B5: Contractor-K | C5: 6124192 | D5: 306 | E5: 18 | F5: 3.4 | G5: 4.7 | H5: 59
A6: Structural Works | B6: Contractor-D | C6: 3366658 | D6: 338 | E6: 8 | F6: 3.1 | G6: 2.1 | H6: 53.9
A7: Structural Works | B7: Contractor-N | C7: 7111231 | D7: 141 | E7: 18 | F7: 4.4 | G7: 10.1 | H7: 94.2
A8: Structural Works | B8: Contractor-A | C8: 6052664 | D8: 262 | E8: 21 | F8: 2.8 | G8: 4.8 | H8: 58.1
A9: Structural Works | B9: Contractor-N | C9: 6312010 | D9: 174 | E9: 25 | F9: 3.6 | G9: 5.2 | H9: 83.8
A10: Structural Works | B10: Contractor-D | C10: 4226208 | D10: 235 | E10: 25 | F10: 4.5 | G10: 3.2 | H10: 62
A11: Structural Works | B11: Contractor-M | C11: 7079774 | D11: 330 | E11: 8 | F11: 3.4 | G11: 11.4 | H11: 99.2
A12: Structural Works | B12: Contractor-H | C12: 6954518 | D12: 234 | E12: 14 | F12: 3.8 | G12: 5.3 | H12: 58.1
A13: MEP Package | B13: Contractor-D | C13: 7221449 | D13: 160 | E13: 10 | F13: 2.6 | G13: 6 | H13: 68.6
A14: MEP Package | B14: Contractor-O | C14: 1360585 | D14: 354 | E14: 5 | F14: 3.2 | G14: 9.3 | H14: 63.6
A15: MEP Package | B15: Contractor-O | C15: 4806314 | D15: 165 | E15: 15 | F15: 2.7 | G15: 11 | H15: 90.8
A16: MEP Package | B16: Contractor-O | C16: 3432532 | D16: 103 | E16: 15 | F16: 2.6 | G16: 6.3 | H16: 61.8
... A44: Landscaping | B44: Contractor-L | C44: 4620485 | D44: 192 | E44: 5 | F44: 2.8 | G44: 1.4 | H44: 58.6
A46: ANALYSIS QUESTIONS
A47: Q1. For each tender package, which contractor offers the lowest bid? Is the lowest bid always the best choice?
A48: Q2. Create a weighted scoring model: 40% Price, 20% Time, 15% Experience, 15% Safety, 10% Defects. Rank contractors.
A49: Q3. Which contractors appear in multiple packages? What is their average bid competitiveness?
A50: Q4. Identify any contractor with Safety Rating < 3.5 AND Defect Rate > 8% — flag as HIGH RISK.
A51: Q5. What is the total project cost if WT selects the lowest bidder for each package vs the highest-scored bidder?
A52: Q6. Create a scatter plot of Bid Amount vs Completion Days — are cheaper bids slower?

Sheet P06-DelayRCA
A1: PROBLEM 6: Project Delay Root Cause Analysis
A2: Scenario: Analyse delay events across projects to find systemic causes.
A4: Delay_ID | B4: Project_ID | C4: Activity | D4: Planned_Start | E4: Actual_Start | F4: Delay_Days | G4: Cause_Category | H4: Responsible_Party
A5: DLY-100 | B5: WT-RES-MEL-05 | C5: Superstructure | D5: 2024-08-11 | E5: 2024-09-23 | F5: 43 | G5: Permit Delay | H5: Force Majeure
A6: DLY-101 | B6: WT-DC-MUM-01 | C6: Handover Prep | D6: 2024-12-03 | E6: 2024-12-22 | F6: 19 | G6: Client Decision Pending | H6: Contractor
A7: DLY-102 | B7: WT-OFF-SYD-02 | C7: Testing & Commissioning | D7: 2024-11-16 | E7: 2024-12-01 | F7: 15 | G7: Material Delay | H7: Contractor
A8: DLY-103 | B8: WT-OFF-SYD-02 | C8: Facade Installation | D8: 2024-11-08 | E8: 2024-11-10 | F8: 2 | G8: Permit Delay | H8: Authority
A9: DLY-104 | B9: WT-MAL-DEL-06 | C9: Testing & Commissioning | D9: 2024-10-26 | E9: 2024-12-01 | F9: 36 | G9: Labour Shortage | H9: Authority
A10: DLY-105 | B10: WT-DC-MUM-01 | C10: Superstructure | D10: 2024-08-06 | E10: 2024-09-01 | F10: 26 | G10: Equipment Breakdown | H10: Authority
A11: DLY-106 | B11: WT-RES-MEL-05 | C11: Landscape | D11: 2024-12-20 | E11: 2024-12-25 | F11: 5 | G11: Labour Shortage | H11: Consultant
A12: DLY-107 | B12: WT-DC-MUM-01 | C12: External Works | D12: 2024-10-25 | E12: 2024-12-08 | F12: 44 | G12: RFI Response Delay | H12: Consultant
A13: DLY-108 | B13: WT-OFF-SYD-02 | C13: Handover Prep | D13: 2024-12-26 | E13: 2025-01-07 | F13: 12 | G13: Labour Shortage | H13: Subcontractor
A14: DLY-109 | B14: WT-MAL-DEL-06 | C14: Foundation | D14: 2024-05-03 | E14: 2024-06-06 | F14: 34 | G14: Labour Shortage | H14: Consultant
A15: DLY-110 | B15: WT-OFF-SYD-02 | C15: MEP Rough-In | D15: 2024-08-13 | E15: 2024-08-28 | F15: 15 | G15: Permit Delay | H15: Authority
A16: DLY-111 | B16: WT-HOS-AKL-03 | C16: Superstructure | D16: 2024-07-07 | E16: 2024-07-20 | F16: 13 | G16: RFI Response Delay | H16: Consultant
... A64: DLY-159 | B64: WT-RES-MEL-05 | C64: External Works | D64: 2024-06-11 | E64: 2024-06-30 | F64: 19 | G64: Permit Delay | H64: Consultant
A66: ANALYSIS QUESTIONS
A67: Q1. What is the most frequent delay cause category? Create a Pareto chart.
A68: Q2. Which responsible party causes the most total delay days?
A69: Q3. For Project WT-DC-MUM-01, what is the cumulative delay and the dominant cause?
A70: Q4. Is there a seasonal pattern in delays? (Hint: check Weather delays by month)
A71: Q5. Which activity is most delay-prone across all projects?
A72: Q6. Calculate the estimated cost of delay per project if the daily burn rate is $15,000.

Sheet P07-CashFlow
A1: PROBLEM 7: Monthly Cash Flow Tracking
A2: Scenario: Track planned vs actual cash inflow/outflow for 4 projects over 12 months.
A4: Month | B4: Project_ID | C4: Planned_Inflow_USD | D4: Actual_Inflow_USD | E4: Planned_Outflow_USD | F4: Actual_Outflow_USD | G4: Net_CashFlow_USD
A5: 2024-01 | B5: WT-DC-MUM-01 | C5: 1554546 | D5: 978713 | E5: 1762133 | F5: 1552987 | G5: =D5-F5 -> -574274
A6: 2024-02 | B6: WT-DC-MUM-01 | C6: 1404044 | D6: 1005450 | E6: 1699137 | F6: 1874303 | G6: =D6-F6 -> -868853
A7: 2024-03 | B7: WT-DC-MUM-01 | C7: 278220 | D7: 293971 | E7: 517137 | F7: 515202 | G7: =D7-F7 -> -221231
A8: 2024-04 | B8: WT-DC-MUM-01 | C8: 1956584 | D8: 1345923 | E8: 226210 | F8: 271228 | G8: =D8-F8 -> 1074695
A9: 2024-05 | B9: WT-DC-MUM-01 | C9: 1032557 | D9: 1026341 | E9: 540723 | F9: 636870 | G9: =D9-F9 -> 389471
A10: 2024-06 | B10: WT-DC-MUM-01 | C10: 807056 | D10: 838024 | E10: 169434 | F10: 161714 | G10: =D10-F10 -> 676310
A11: 2024-07 | B11: WT-DC-MUM-01 | C11: 1464127 | D11: 957027 | E11: 852634 | F11: 809658 | G11: =D11-F11 -> 147369
A12: 2024-08 | B12: WT-DC-MUM-01 | C12: 1544929 | D12: 1346637 | E12: 1185809 | F12: 1377010 | G12: =D12-F12 -> -30373
A13: 2024-09 | B13: WT-DC-MUM-01 | C13: 481437 | D13: 493728 | E13: 1131510 | F13: 1069834 | G13: =D13-F13 -> -576106
A14: 2024-10 | B14: WT-DC-MUM-01 | C14: 1896205 | D14: 1244523 | E14: 490775 | F14: 542744 | G14: =D14-F14 -> 701779
A15: 2024-11 | B15: WT-DC-MUM-01 | C15: 1559552 | D15: 1136340 | E15: 540487 | F15: 462078 | G15: =D15-F15 -> 674262
A16: 2024-12 | B16: WT-DC-MUM-01 | C16: 906975 | D16: 902788 | E16: 1340723 | F16: 1456079 | G16: =D16-F16 -> -553291
... A52: 2024-12 | B52: WT-ITP-BLR-04 | C52: 925949 | D52: 627386 | E52: 545272 | F52: 642381 | G52: =D52-F52 -> -14995
A54: ANALYSIS QUESTIONS
A55: Q1. Which project had negative net cash flow for the most months?
A56: Q2. What is the cumulative cash position for each project at end of December 2024?
A57: Q3. Create a line chart of monthly net cash flow for all 4 projects.
A58: Q4. In which months did actual inflow fall below 70% of planned? Flag as collection risk.
A59: Q5. What is the total cash surplus/deficit across all projects?
A60: Q6. Calculate the cash flow forecast accuracy: (Actual Inflow / Planned Inflow) × 100.

Sheet P08-ChangeOrder
A1: PROBLEM 8: Change Order Impact Analysis
A2: Scenario: Evaluate cost and time impact of change orders (VOs) on ongoing projects.
A4: VO_Number | B4: Project_ID | C4: Description | D4: Initiated_By | E4: Cost_Impact_USD | F4: Time_Impact_Days | G4: Status | H4: Date_Raised
A5: VO-200 | B5: WT-DC-MUM-01 | C5: Additional MEP riser | D5: Architect | E5: 444793 | F5: -4 | G5: Pending | H5: 2024-04-15
A6: VO-201 | B6: WT-DC-MUM-01 | C6: Design revision - column grid | D6: Client | E6: 268127 | F6: -2 | G6: Pending | H6: 2025-01-14
A7: VO-202 | B7: WT-DC-MUM-01 | C7: Upgraded HVAC system | D7: Architect | E7: 45722 | F7: 29 | G7: Pending | H7: 2025-01-21
A8: VO-203 | B8: WT-DC-MUM-01 | C8: Client-requested floor upgrade | D8: Contractor | E8: 45536 | F8: 15 | G8: Rejected | H8: 2024-05-01
A9: VO-204 | B9: WT-HOS-AKL-03 | C9: Basement depth increase | D9: Consultant | E9: 492282 | F9: 28 | G9: Pending | H9: 2024-07-30
A10: VO-205 | B10: WT-HOS-AKL-03 | C10: Scope reduction - parking level | D10: Client | E10: 383761 | F10: 6 | G10: Under Review | H10: 2024-10-11
A11: VO-206 | B11: WT-RES-MEL-05 | C11: Additional MEP riser | D11: Contractor | E11: 787324 | F11: 19 | G11: Rejected | H11: 2024-12-22
A12: VO-207 | B12: WT-RES-MEL-05 | C12: Upgraded HVAC system | D12: Consultant | E12: 114455 | F12: 19 | G12: Pending | H12: 2025-01-21
A13: VO-208 | B13: WT-RES-MEL-05 | C13: Regulatory compliance addition | D13: Consultant | E13: 115344 | F13: 4 | G13: Under Review | H13: 2024-01-30
A14: VO-209 | B14: WT-RES-MEL-05 | C14: Upgraded HVAC system | D14: Consultant | E14: 207286 | F14: 10 | G14: Rejected | H14: 2024-04-14
A15: VO-210 | B15: WT-HOS-AKL-03 | C15: Revised electrical layout | D15: Client | E15: 767024 | F15: 23 | G15: Rejected | H15: 2024-02-17
A16: VO-211 | B16: WT-OFF-SYD-02 | C16: Additional MEP riser | D16: Contractor | E16: 195489 | F16: -3 | G16: Approved | H16: 2024-04-06
... A49: VO-244 | B49: WT-HOS-AKL-03 | C49: Design revision - column grid | D49: Consultant | E49: -108463 | F49: 6 | G49: Under Review | H49: 2024-08-17
A51: ANALYSIS QUESTIONS
A52: Q1. What is the total approved cost impact of all change orders per project?
A53: Q2. Who initiates the most change orders — Client, Consultant, or Contractor?
A54: Q3. What % of change orders are still Pending or Under Review? What is the potential cost exposure?
A55: Q4. Is there a correlation between cost impact and time impact of VOs?
